Workbook

Sheet Summary
B2: Summary
B3: Restaurant Name | C3: L'amore
B4: Restaurant Address | C4: 3035 Peachtree Rd NE Atlanta, GA 30305
B5: Number of Seats | C5: 50

Sheet Table of Contents
A1: HADM 3403 – Restaurant Business Plan Project
A2: Menu Mix
A3: Hourly Customer
A4: Salaries
A5: Preopening
A6: Income Statement
A7: Monthly Income Statement
A8: 10-year Income Statement
A9: Loan Amortization
A10: Cash Flow Projection
A11: Valuation

Sheet Menu Mix
A1: Menu Mix with Menu Engineering
A2: =Summary!C3 -> L'amore
A3: Beverages | B3: Menu Item | C3: Menu Price | D3: Cost | E3: Cost % | F3: Popularity | G3: Per Capita Spending | H3: Total Cost
B4: Espresso Martini | C4: 12 | D4: 1.25 | E4: =IF(D4="","",D4/C4) -> 0.10416667 | F4: 0.15 | G4: =IF(C4="","",C4*F4) -> 1.8 | H4: =IF(D4="","",D4*F4) -> 0.1875
B5: Bellini | C5: 13 | D5: 1 | E5: =IF(D5="","",D5/C5) -> 0.076923077 | F5: 0.05 | G5: =IF(C5="","",C5*F5) -> 0.65 | H5: =IF(D5="","",D5*F5) -> 0.05
B6: Negroni | C6: 14 | D6: 1 | E6: =IF(D6="","",D6/C6) -> 0.071428571 | F6: 0.1 | G6: =IF(C6="","",C6*F6) -> 1.4 | H6: =IF(D6="","",D6*F6) -> 0.1
B7: Red wine | C7: 11 | D7: 4 | E7: =IF(D7="","",D7/C7) -> 0.36363636 | F7: 0.3 | G7: =IF(C7="","",C7*F7) -> 3.3 | H7: =IF(D7="","",D7*F7) -> 1.2
B8: Non-alcoholic sparkling wine | C8: 9 | D8: 3 | E8: =IF(D8="","",D8/C8) -> 0.33333333 | F8: 0.1 | G8: =IF(C8="","",C8*F8) -> 0.9 | H8: =IF(D8="","",D8*F8) -> 0.3
B9: White wine | C9: 11 | D9: 4 | E9: =IF(D9="","",D9/C9) -> 0.36363636 | F9: 0.3 | G9: =IF(C9="","",C9*F9) -> 3.3 | H9: =IF(D9="","",D9*F9) -> 1.2
A10: Per Capita Sales & Cost of Beverages Menu | G10: =SUM(G4:G9) -> 11.35 | H10: =SUM(H4:H9) -> 3.0375
A11: Food | B11: Menu Item | C11: Menu Price | D11: Cost | E11: Cost % | F11: Popularity | G11: Per Capita Spending | H11: Total Cost
A12: Appetizers | B12: Arancini | C12: 12 | D12: 5 | E12: =IF(D12="","",D12/C12) -> 0.41666667 | F12: 0.03 | G12: =IF(C12="","",C12*F12) -> 0.36 | H12: =IF(D12="","",D12*F12) -> 0.15
B13: Bruschetta | C13: 14 | D13: 6 | E13: =IF(D13="","",D13/C13) -> 0.42857143 | F13: 0.03 | G13: =IF(C13="","",C13*F13) -> 0.42 | H13: =IF(D13="","",D13*F13) -> 0.18
B14: Caprese | C14: 10 | D14: 4.5 | E14: =IF(D14="","",D14/C14) -> 0.45 | F14: 0.02 | G14: =IF(C14="","",C14*F14) -> 0.2 | H14: =IF(D14="","",D14*F14) -> 0.09
B15: Cheese board | C15: 17 | D15: 8 | E15: =IF(D15="","",D15/C15) -> 0.47058824 | F15: 0.02 | G15: =IF(C15="","",C15*F15) -> 0.34 | H15: =IF(D15="","",D15*F15) -> 0.16
A16: Salads | B16: Greek salad | C16: 11 | D16: 5 | E16: =IF(D16="","",D16/C16) -> 0.45454545 | F16: 0.03 | G16: =IF(C16="","",C16*F16) -> 0.33 | H16: =IF(D16="","",D16*F16) -> 0.15
B17: Caesar salad | C17: 12 | D17: 4.5 | E17: =IF(D17="","",D17/C17) -> 0.375 | F17: 0.03 | G17: =IF(C17="","",C17*F17) -> 0.36 | H17: =IF(D17="","",D17*F17) -> 0.135
A18: Entrees | B18: Bolognese | C18: 21 | D18: 10 | E18: =IF(D18="","",D18/C18) -> 0.47619048 | F18: 0.04 | G18: =IF(C18="","",C18*F18) -> 0.84 | H18: =IF(D18="","",D18*F18) -> 0.4
B19: Amore (Rose Pasta) | C19: 23 | D19: 11 | E19: =IF(D19="","",D19/C19) -> 0.47826087 | F19: 0.06 | G19: =IF(C19="","",C19*F19) -> 1.38 | H19: =IF(D19="","",D19*F19) -> 0.66
B20: Polenta | C20: 19 | D20: 9 | E20: =IF(D20="","",D20/C20) -> 0.47368421 | F20: 0.05 | G20: =IF(C20="","",C20*F20) -> 0.95 | H20: =IF(D20="","",D20*F20) -> 0.45
B21: Squash Ravioli | C21: 19 | D21: 9 | E21: =IF(D21="","",D21/C21) -> 0.47368421 | F21: 0.03 | G21: =IF(C21="","",C21*F21) -> 0.57 | H21: =IF(D21="","",D21*F21) -> 0.27
B22: Tortellini soup | C22: 18 | D22: 8 | E22: =IF(D22="","",D22/C22) -> 0.44444444 | F22: 0.04 | G22: =IF(C22="","",C22*F22) -> 0.72 | H22: =IF(D22="","",D22*F22) -> 0.32
B23: Gnocchi | C23: 17 | D23: 8 | E23: =IF(D23="","",D23/C23) -> 0.47058824 | F23: 0.03 | G23: =IF(C23="","",C23*F23) -> 0.51 | H23: =IF(D23="","",D23*F23) -> 0.24
A24: Desserts | B24: Panna cotta | C24: 7.5 | D24: 3 | E24: =IF(D24="","",D24/C24) -> 0.4 | F24: 0.02 | G24: =IF(C24="","",C24*F24) -> 0.15 | H24: =IF(D24="","",D24*F24) -> 0.06
B25: Cannoli | C25: 6 | D25: 2.5 | E25: =IF(D25="","",D25/C25) -> 0.41666667 | F25: 0.03 | G25: =IF(C25="","",C25*F25) -> 0.18 | H25: =IF(D25="","",D25*F25) -> 0.075
B26: Tiramisu | C26: 8 | D26: 3.5 | E26: =IF(D26="","",D26/C26) -> 0.4375 | F26: 0.04 | G26: =IF(C26="","",C26*F26) -> 0.32 | H26: =IF(D26="","",D26*F26) -> 0.14
A27: Per Capita Sales & Cost of Food Menu | G27: =SUM(G12:G15) -> 1.32 | H27: =SUM(H12:H15) -> 0.58
A28: Retail | B28: Menu Item | C28: Menu Price | D28: Cost | E28: Cost % | F28: Popularity | G28: Per Capita Spending | H28: Total Cost
B29: L'amore meal for two | C29: 37 | D29: 16 | E29: =IF(D29="","",D29/C29) -> 0.43243243 | F29: 0.09 | G29: =IF(C29="","",C29*F29) -> 3.33 | H29: =IF(D29="","",D29*F29) -> 1.44
B30: Dessert Tour for four | C30: 24 | D30: 11 | E30: =IF(D30="","",D30/C30) -> 0.45833333 | F30: 0.07 | G30: =IF(C30="","",C30*F30) -> 1.68 | H30: =IF(D30="","",D30*F30) -> 0.77
B31: Pasta Sampler for two | C31: 29 | D31: 13 | E31: =IF(D31="","",D31/C31) -> 0.44827586 | F31: 0.06 | G31: =IF(C31="","",C31*F31) -> 1.74 | H31: =IF(D31="","",D31*F31) -> 0.78
B32: 4 drinks deal | C32: 37 | D32: 13 | E32: =IF(D32="","",D32/C32) -> 0.35135135 | F32: 0.05 | G32: =IF(C32="","",C32*F32) -> 1.85 | H32: =IF(D32="","",D32*F32) -> 0.65
B33: Appetizer Plate | C33: 21 | D33: 10 | E33: =IF(D33="","",D33/C33) -> 0.47619048 | F33: 0.03 | G33: =IF(C33="","",C33*F33) -> 0.63 | H33: =IF(D33="","",D33*F33) -> 0.3
A34: Per Capita Sales & Cost of Retail Menu | G34: =SUM(G29:G33) -> 9.23 | H34: =SUM(H29:H33) -> 3.94
A35: Total Per Capita Spending for Beverages | G35: =G10 -> 11.35 | H35: =H10 -> 3.0375
A36: Total Per Capita Spending for Food | G36: =G27 -> 1.32 | H36: =H27 -> 0.58
A37: Total Per Capita Spending for Retail | G37: =G34 -> 9.23 | H37: =H34 -> 3.94
A38: Total Beverage, Food, and Retail Spending per Capita | G38: =SUM(G35:G37) -> 21.9 | H38: =SUM(H35:H37) -> 7.5575
A40: Overall Food & Beverage Cost Percentage | G40: =IFERROR(H38/G38,0) -> 0.34509132

Sheet Hourly Customer
A1: =Summary!C3 -> L'amore
A2: Hourly Customer Count Projection | L2: # of guests to serve per position | M2: Position | N2: Sun | O2: Mon | P2: Tue | Q2: Wed | R2: Thu | S2: Fri | T2: Sat | U2: Weekly Total | V2: Daily Total
B3: # of seats | C3: =Summary!C5 -> 50 | L3: 65 | M3: AM Bartender | N3: =C18/$L$3 -> 4.1230769 | O3: =D18/$L$3 -> 3.3384615 | P3: =E18/$L$3 -> 3.1076923 | Q3: =F18/$L$3 -> 3.2 | R3: =G18/$L$3 -> 3.3692308 | S3: =H18/$L$3 -> 4.7692308 | T3: =I18/$L$3 -> 5.3230769 | U3: =SUM(M3:T3) -> 27.230769 | V3: =U3/7 -> 3.8901099
C4: Sun | D4: Mon | E4: Tue | F4: Wed | G4: Thu | H4: Fri | I4: Sat | J4: Total | L4: 65 | M4: PM Bartender | N4: =C18/$L$4 -> 4.1230769 | O4: =D18/$L$4 -> 3.3384615 | P4: =E18/$L$4 -> 3.1076923 | Q4: =F18/$L$4 -> 3.2 | R4: =G18/$L$4 -> 3.3692308 | S4: =H18/$L$4 -> 4.7692308 | T4: =I18/$L$4 -> 5.3230769 | U4: =SUM(M4:T4) -> 27.230769 | V4: =U4/7 -> 3.8901099
B5: 11:00 - 12:00 | C5: 23 | D5: 15 | E5: 18 | F5: 18 | G5: 19 | H5: 21 | I5: 25 | J5: =SUM(C5:I5) -> 139 | L5: 45 | M5: AM Cook | N5: =C18/$L$5 -> 5.9555556 | O5: =D18/$L$5 -> 4.8222222 | P5: =E18/$L$5 -> 4.4888889 | Q5: =F18/$L$5 -> 4.6222222 | R5: =G18/$L$5 -> 4.8666667 | S5: =H18/$L$5 -> 6.8888889 | T5: =I18/$L$5 -> 7.6888889 | U5: =SUM(M5:T5) -> 39.333333 | V5: =U5/7 -> 5.6190476
B6: 12:00 - 01:00 | C6: 25 | D6: 23 | E6: 20 | F6: 18 | G6: 19 | H6: 24 | I6: 29 | J6: =SUM(C6:I6) -> 158 | L6: 45 | M6: PM Cook | N6: =$C$18/$L$6 -> 5.9555556 | O6: =$D$18/$L$6 -> 4.8222222 | P6: =E18/$L$6 -> 4.4888889 | Q6: =F18/$L$6 -> 4.6222222 | R6: =G18/$L$6 -> 4.8666667 | S6: =H18/$L$6 -> 6.8888889 | T6: =I18/$L$6 -> 7.6888889 | U6: =SUM(M6:T6) -> 39.333333 | V6: =U6/7 -> 5.6190476
B7: 01:00 - 02:00 | C7: 23 | D7: 12 | E7: 13 | F7: 20 | G7: 15 | H7: 16 | I7: 20 | J7: =SUM(C7:I7) -> 119 | L7: 40 | M7: AM Server | N7: =$C$18/$L$7 -> 6.7 | O7: =$D$18/$L$7 -> 5.425 | P7: =E18/$L$7 -> 5.05 | Q7: =F18/$L$7 -> 5.2 | R7: =G18/$L$7 -> 5.475 | S7: =H18/$L$7 -> 7.75 | T7: =I18/$L$7 -> 8.65 | U7: =SUM(M7:T7) -> 44.25 | V7: =U7/7 -> 6.3214286
B8: 02:00 - 03:00 | C8: 13 | D8: 8 | E8: 9 | F8: 7 | G8: 8 | H8: 15 | I8: 21 | J8: =SUM(C8:I8) -> 81 | L8: 40 | M8: PM Server | N8: =$C$18/$L$8 -> 6.7 | O8: =$D$18/$L$8 -> 5.425 | P8: =E18/$L$8 -> 5.05 | Q8: =F$18/$L$8 -> 5.2 | R8: =G18/$L$8 -> 5.475 | S8: =H18/$L$8 -> 7.75 | T8: =I18/$L$8 -> 8.65 | U8: =SUM(M8:T8) -> 44.25 | V8: =U8/7 -> 6.3214286
B9: 03:00 - 04:00 | C9: 12 | D9: 9 | E9: 8 | F9: 8 | G9: 7 | H9: 11 | I9: 19 | J9: =SUM(C9:I9) -> 74
B10: 04:00 - 05:00 | C10: 11 | D10: 12 | E10: 12 | F10: 11 | G10: 10 | H10: 13 | I10: 14 | J10: =SUM(C10:I10) -> 83
B11: 05:00 - 06:00 | C11: 35 | D11: 25 | E11: 24 | F11: 23 | G11: 24 | H11: 38 | I11: 37 | J11: =SUM(C11:I11) -> 206
B12: 06:00 - 07:00 | C12: 48 | D12: 36 | E12: 32 | F12: 31 | G12: 34 | H12: 44 | I12: 49 | J12: =SUM(C12:I12) -> 274
B13: 07:00 - 08:00 | C13: 45 | D13: 31 | E13: 30 | F13: 32 | G13: 35 | H13: 43 | I13: 45 | J13: =SUM(C13:I13) -> 261
B14: 08:00 - 09:00 | C14: 33 | D14: 26 | E14: 21 | F14: 20 | G14: 23 | H14: 34 | I14: 35 | J14: =SUM(C14:I14) -> 192
B15: 09:00-10:00 | C15: - | D15: 11 | E15: 9 | F15: 10 | G15: 10 | H15: 31 | I15: 29 | J15: =SUM(C15:I15) -> 100
B16: 10:00-10:30 | C16: - | D16: 9 | E16: 6 | F16: 10 | G16: 9 | H16: 20 | I16: 23 | J16: =SUM(C16:I16) -> 77
B17: 10:30-11:00 | C17: - | D17: 3 | E17: 5 | F17: 4 | G17: 6 | H17: 14 | I17: 13 | J17: =SUM(C17:I17) -> 45
B18: Total Count | C18: =SUM(C5:C16) -> 268 | D18: =SUM(D5:D16) -> 217 | E18: =SUM(E5:E16) -> 202 | F18: =SUM(F5:F16) -> 208 | G18: =SUM(G5:G17) -> 219 | H18: =SUM(H5:H16) -> 310 | I18: =SUM(I5:I16) -> 346 | J18: =SUM(C18:I18) -> 1770
B19: Seat Turnover | C19: =IF($C$3="","",C18/$C$3) -> 5.36 | D19: =IF($C$3="","",D18/$C$3) -> 4.34 | E19: =IF($C$3="","",E18/$C$3) -> 4.04 | F19: =IF($C$3="","",F18/$C$3) -> 4.16 | G19: =IF($C$3="","",G18/$C$3) -> 4.38 | H19: =IF($C$3="","",H18/$C$3) -> 6.2 | I19: =IF($C$3="","",I18/$C$3) -> 6.92 | J19: =IF($C$3="","",J18/$C$3) -> 35.4
B20: Avg. Check | C20: ='Menu Mix'!$G$38 -> 21.9 | D20: ='Menu Mix'!$G$38 -> 21.9 | E20: ='Menu Mix'!$G$38 -> 21.9 | F20: ='Menu Mix'!$G$38 -> 21.9 | G20: ='Menu Mix'!$G$38 -> 21.9 | H20: ='Menu Mix'!$G$38 -> 21.9 | I20: ='Menu Mix'!$G$38 -> 21.9 | J20: =IFERROR(J22/$J$18,0) -> 21.9
B21: Avg. Check Cost | C21: ='Menu Mix'!$H$38 -> 7.5575 | D21: ='Menu Mix'!$H$38 -> 7.5575 | E21: ='Menu Mix'!$H$38 -> 7.5575 | F21: ='Menu Mix'!$H$38 -> 7.5575 | G21: ='Menu Mix'!$H$38 -> 7.5575 | H21: ='Menu Mix'!$H$38 -> 7.5575 | I21: ='Menu Mix'!$H$38 -> 7.5575 | J21: =IFERROR(J23/$J$18,0) -> 7.5575
B22: Sales Estimate | C22: =C18*C20 -> 5869.2 | D22: =D18*D20 -> 4752.3 | E22: =E18*E20 -> 4423.8 | F22: =F18*F20 -> 4555.2 | G22: =G18*G20 -> 4796.1 | H22: =H18*H20 -> 6789 | I22: =I18*I20 -> 7577.4 | J22: =SUM(C22:I22) -> 38763
B23: Cost Estimate | C23: =C18*C21 -> 2025.41 | D23: =D18*D21 -> 1639.9775 | E23: =E18*E21 -> 1526.615 | F23: =F18*F21 -> 1571.96 | G23: =G18*G21 -> 1655.0925 | H23: =H18*H21 -> 2342.825 | I23: =I18*I21 -> 2614.895 | J23: =SUM(C23:I23) -> 13376.775
B25: Daily Total Sales | C25: =C22 -> 5869.2 | D25: =D22 -> 4752.3 | E25: =E22 -> 4423.8 | F25: =F22 -> 4555.2 | G25: =G22 -> 4796.1 | H25: =H22 -> 6789 | I25: =I22 -> 7577.4 | J25: =J22 -> 38763
B26: Daily Customer | C26: =C18 -> 268 | D26: =D18 -> 217 | E26: =E18 -> 202 | F26: =F18 -> 208 | G26: =G18 -> 219 | H26: =H18 -> 310 | I26: =I18 -> 346 | J26: =J18 -> 1770
B27: Daily Seat Turnover | C27: =C19 -> 5.36 | D27: =D19 -> 4.34 | E27: =E19 -> 4.04 | F27: =F19 -> 4.16 | G27: =G19 -> 4.38 | H27: =H19 -> 6.2 | I27: =I19 -> 6.92 | J27: =J19 -> 35.4

Sheet Hourly Labor
A1: Hourly Employee Schedule Projection (Normal Condition)
B2: Department | C2: Front
C3: Sun | D3: Mon | E3: Tue | F3: Wed | G3: Thu | H3: Fri | I3: Sat | J3: Total
B4: 08:00 - 09:00 | J4: =SUM(C4:I4) -> 0
B5: 09:00 - 10:00 | J5: =SUM(C5:I5) -> 0
B6: 10:00 - 11:00 | J6: =SUM(C6:I6) -> 0
B7: 11:00 - 12:00 | J7: =SUM(C7:I7) -> 0
B8: 12:00 - 01:00 | J8: =SUM(C8:I8) -> 0
B9: 01:00 - 02:00 | J9: =SUM(C9:I9) -> 0
B10: 02:00 - 03:00 | J10: =SUM(C10:I10) -> 0
B11: 03:00 - 04:00 | J11: =SUM(C11:I11) -> 0
B12: 04:00 - 05:00 | J12: =SUM(C12:I12) -> 0
B13: 05:00 - 06:00 | J13: =SUM(C13:I13) -> 0
B14: 06:00 - 07:00 | J14: =SUM(C14:I14) -> 0
B15: 07:00 - 08:00 | J15: =SUM(C15:I15) -> 0
... B17: 09:00 - 10:00 | J17: =SUM(C17:I17) -> 0
B18: Total Hours | C18: =SUM(C4:C17) -> 0 | D18: =SUM(D4:D17) -> 0 | E18: =SUM(E4:E17) -> 0 | F18: =SUM(F4:F17) -> 0 | G18: =SUM(G4:G17) -> 0 | H18: =SUM(H4:H17) -> 0 | I18: =SUM(I4:I17) -> 0 | J18: =SUM(C18:I18) -> 0
B20: Department | C20: Back
B21: 07:00 - 08:00 | J21: =SUM(C21:I21) -> 0
B22: 08:00 - 09:00 | J22: =SUM(C22:I22) -> 0
B23: 09:00 - 10:00 | J23: =SUM(C23:I23) -> 0
B24: 10:00 - 11:00 | J24: =SUM(C24:I24) -> 0
B25: 11:00 - 12:00 | J25: =SUM(C25:I25) -> 0
B26: Total Hours | C26: =SUM(C20:C25) -> 0 | D26: =SUM(D20:D25) -> 0 | E26: =SUM(E20:E25) -> 0 | F26: =SUM(F20:F25) -> 0 | G26: =SUM(G20:G25) -> 0 | H26: =SUM(H20:H25) -> 0 | I26: =SUM(I20:I25) -> 0 | J26: =SUM(C26:I26) -> 0

Sheet Salaries
C1: Annual | D1: Monthly | E1: Weekly | F1: Daily | G1: Hours per shift | H1: # Employees per day | I1: Hourly wage
B2: Salaried Employees
A3: FOH | B3: General Manager | C3: 59000 | D3: =C3/12 -> 4916.6667 | E3: =C3/52 -> 1134.6154 | F3: =C3/365 -> 161.64384 | G3: n/a | H3: n/a | I3: n/a
B4: Assistant Manager 1 | C4: 46000 | D4: =C4/12 -> 3833.3333 | E4: =C4/52 -> 884.61538 | F4: =C4/365 -> 126.0274 | G4: n/a | H4: n/a | I4: n/a
A7: BOH
B10: Total Salaried Wages | C10: =SUM(C3:C9) -> 105000 | D10: =SUM(D3:D9) -> 8750 | E10: =SUM(E3:E9) -> 2019.2308 | F10: =SUM(F3:F9) -> 287.67123
B11: Hourly Employees
A12: FOH | B12: ='Hourly Customer'!M3 -> AM Bartender | C12: =D12*12 -> 93384.111 | D12: =E12*4.33 -> 7782.0092 | E12: =F12*7 -> 1797.2308 | F12: =I12*H12*G12 -> 256.74725 | G12: 6 | H12: ='Hourly Customer'!V3 -> 3.8901099 | I12: 11
B13: ='Hourly Customer'!M4 -> PM Bartender | C13: =D13*12 -> 93384.111 | D13: =E13*4.33 -> 7782.0092 | E13: =F13*7 -> 1797.2308 | F13: =I13*H13*G13 -> 256.74725 | G13: 6 | H13: ='Hourly Customer'!V4 -> 3.8901099 | I13: 11
B14: ='Hourly Customer'!M7 -> AM Server | C14: =D14*12 -> 165544.56 | D14: =E14*4.33 -> 13795.38 | E14: =F14*7 -> 3186 | F14: =I14*H14*G14 -> 455.14286 | G14: 6 | H14: ='Hourly Customer'!V7 -> 6.3214286 | I14: 12
B15: ='Hourly Customer'!M8 -> PM Server | C15: =D15*12 -> 165544.56 | D15: =E15*4.33 -> 13795.38 | E15: =F15*7 -> 3186 | F15: =I15*H15*G15 -> 455.14286 | G15: 6 | H15: ='Hourly Customer'!V8 -> 6.3214286 | I15: 12
A16: BOH | B16: ='Hourly Customer'!M5 -> AM Cook | C16: =D16*12 -> 171675.84 | D16: =E16*4.33 -> 14306.32 | E16: =F16*7 -> 3304 | F16: =I16*H16*G16 -> 472 | G16: 6 | H16: ='Hourly Customer'!V5 -> 5.6190476 | I16: 14
B17: ='Hourly Customer'!M6 -> PM Cook | C17: =D17*12 -> 171675.84 | D17: =E17*4.33 -> 14306.32 | E17: =F17*7 -> 3304 | F17: =I17*H17*G17 -> 472 | G17: 6 | H17: ='Hourly Customer'!V6 -> 5.6190476 | I17: 14
B18: Total Hourly Wages | C18: =SUM(C12:C17) -> 861209.02 | D18: =SUM(D12:D17) -> 71767.418 | E18: =SUM(E12:E17) -> 16574.462 | F18: =SUM(F12:F17) -> 2367.7802
B19: Total Wages | C19: =C10+C18 -> 966209.02 | D19: =D10+D18 -> 80517.418 | E19: =E10+E18 -> 18593.692 | F19: =F10+F18 -> 2655.4515

Sheet Preopening
B3: Preopening Checklist Summary
B4: 1. Preopening costs to be capitalized | C4: =D14 -> 126600
B5: 2. Equipment | C5: =D36 -> 92669.99
B6: 3. Cash | C6: =D39 -> 30000 | D6: =SUM(C4:C6) -> 249269.99
B8: Preopening Costs to be Capitalized
B9: Legal services (permits, etc) | C9: 9000
B10: Marketing | C10: 3000
B11: Consultant fees | C11: 4000
B12: Insurance (general liability/worker’s compensation/property casualty) | C12: 5000
B13: Prepaid rent ($9/sq foot @ 1,200 sq. feet) | C13: 18000
B14: Remodeling/Cosmetic/Construction ($73 sq/ft. x 1,200 square feet) | C14: 87600 | D14: =SUM(C9:C14) -> 126600
B16: Equipment/FFE
B17: Pasta maker | C17: 1789
B18: Pasta cooker | C18: 3130
B19: Hot water machine | C19: 455
B20: Meat slicer | C20: 4499
B21: Scales | C21: 119.99
B22: Dough Sheeter | C22: 4589
B23: Pizza oven | C23: 10506
B24: Food service equipment:
B25: Refrigeration | C25: 3398
B26: Stove/oven | C26: 13128
B27: Dishwasher | C27: 2749
B28: Ice machine | C28: 3398
B29: Sinks | C29: 959
B30: Countertops/storage bins | C30: 6000
B31: POS system/Register | C31: 2000
B32: Ventilation/Security | C32: 9000
B33: Office Equipment (computer, phone, file cabinets) | C33: 3750
B34: Furniture | C34: 21700
B35: Signage | C35: 1000
B36: WIFI setup (router, etc) | C36: 500 | D36: =SUM(C17:C36) -> 92669.99
B38: Cash (Operating Capital)
B39: Cash Reserves ($10,000/month x 2 – 3 months) | C39: 30000 | D39: =SUM(C39:C39) -> 30000
B43: Depreciation (straight-line, $0 salvage value, 5 year useful life) | C43: =(D6-0)/5 -> 49853.998
B45: Balance Sheet:
B46: Assets (preopening) | C46: =D6 -> 249269.99
B47: Liabilities
B48: Notes Payable | C48: =C46-C50-C54-C51-C52-C53 -> 174488.99
B49: Equity
...

Sheet Income Statement
B1: Note: This is an example that serves as a reference for your business. For your own business, give your best estimate for some of these costs. In some instances, such as insurance, you can actually obtain a quote from a business.
C2: =Summary!C3 -> L'amore
C3: Income Statement (Optimal Year)
C4: Year Ended 12/31/20XX
D5: $ | E5: % of Revenue
B6: REVENUES | D6: ='Hourly Customer'!J22*52 -> 2015676 | E6: 1
B8: COST OF SALES | D8: ='Hourly Customer'!J23*52 -> 695592.3 | E8: =IFERROR(D8/$D$6,0) -> 0.34509132
B10: LABOR
B11: Salaries | C11: =Salaries!C10 -> 105000 | E11: =IFERROR(C11/$D$6,0) -> 0.052091705
B12: Wages | C12: =Salaries!C18 -> 861209.02 | E12: =IFERROR(C12/$D$6,0) -> 0.42725568
B13: Payroll tax (7.65%) | C13: =(C11+C12)*0.0765 -> 73914.99 | E13: =IFERROR(C13/$D$6,0) -> 0.036670075
B14: Group Insurance (2.7%) | C14: =(C11+C12)*0.027 -> 26087.644 | E14: =IFERROR(C14/$D$6,0) -> 0.012942379
B15: Total Payroll & Related expenses | D15: =SUM(C11:C14) -> 1066211.7 | E15: =IFERROR(D15/$D$6,0) -> 0.52895984
B17: PRIME COST (FOOD + BEVERAGE + LABOR) | D17: =D8+D15 -> 1761804 | E17: =IFERROR(D17/$D$6,0) -> 0.87405116
B19: OTHER CONTROLLABLE EXPENSES
B20: Operating expenses
B21: China & silverware (1%) | C21: =D6*0.01 -> 20156.76 | E21: =IFERROR(C21/$D$6,0) -> 0.01
B22: Cleaning (3rd party contracted) | C22: 7500 | E22: =IFERROR(C22/$D$6,0) -> 0.0037208361
B23: Exterminating | C23: 4000 | E23: =IFERROR(C23/$D$6,0) -> 0.0019844459
B24: Operating supplies (stir sticks, etc) | C24: 15000 | E24: =IFERROR(C24/$D$6,0) -> 0.0074416722
B25: Flowers & Decoration | C25: 9000 | E25: =IFERROR(C25/$D$6,0) -> 0.0044650033
B26: Napkins | C26: 8700 | E26: =IFERROR(C26/$D$6,0) -> 0.0043161699
B27: Cleaning supplies | C27: 2500 | E27: =IFERROR(C27/$D$6,0) -> 0.0012402787
B28: Trash removal | C28: 2200 | E28: =IFERROR(C28/$D$6,0) -> 0.0010914453
B29: Total Operating expenses | C29: =SUM(C21:C28) -> 69056.76 | E29: =IFERROR(C29/$D$6,0) -> 0.034259851
B31: Marketing
B32: Local promotion | C32: 9500 | E32: =IFERROR(C32/$D$6,0) -> 0.004713059
B33: Redemption (coupon, etc.) | C33: 6000 | E33: =IFERROR(C33/$D$6,0) -> 0.0029766689
B34: Total marketing expense | C34: =SUM(C32:C33) -> 15500 | E34: =IFERROR(C34/$D$6,0) -> 0.0076897279
B36: Energy
B37: Electricity | C37: 10000 | E37: =IFERROR(C37/$D$6,0) -> 0.0049611148
B38: Gas | C38: 24000 | E38: =IFERROR(C38/$D$6,0) -> 0.011906675
B39: Water/Sewerage | C39: 9000 | E39: =IFERROR(C39/$D$6,0) -> 0.0044650033
B40: Total energy expenses | C40: =SUM(C37:C39) -> 43000 | E40: =IFERROR(C40/$D$6,0) -> 0.021332794
B42: Administrative
B43: Credit card fee (2%) @ 90% CC usage | C43: =(D6*0.9)*0.02 -> 36282.168 | E43: =IFERROR(C43/$D$6,0) -> 0.018
B44: Office Supplies | C44: 1700 | E44: =IFERROR(C44/$D$6,0) -> 0.00084338951
B45: Telephone | C45: 1300 | E45: =IFERROR(C45/$D$6,0) -> 0.00064494492
B46: General Insurance (Fire, Liability, Work comp, casualty) | C46: 15000 | E46: =IFERROR(C46/$D$6,0) -> 0.0074416722
B47: Total administrative expenses | C47: =SUM(C43:C46) -> 54282.168 | E47: =IFERROR(C47/$D$6,0) -> 0.026930007
...

Sheet Monthly IS
A1: Pro Forma Income Statement Monthly Breakdown (Optimal Year)
B2: Period 1 | C2: Period 2 | D2: Period 3 | E2: Period 4 | F2: Period 5 | G2: Period 6 | H2: Period 7 | I2: Period 8 | J2: Period 9 | K2: Period 10 | L2: Period 11 | M2: Period 12 | N2: Period 13 | O2: Annual Total
A3: Revenues | B3: ='Hourly Customer'!$J$22*4 -> 155052 | C3: ='Hourly Customer'!$J$22*4 -> 155052 | D3: ='Hourly Customer'!$J$22*4 -> 155052 | E3: ='Hourly Customer'!$J$22*4 -> 155052 | F3: ='Hourly Customer'!$J$22*4 -> 155052 | G3: ='Hourly Customer'!$J$22*4 -> 155052 | H3: ='Hourly Customer'!$J$22*4 -> 155052 | I3: ='Hourly Customer'!$J$22*4 -> 155052 | ... N3: ='Hourly Customer'!$J$22*4 -> 155052 | O3: =SUM(B3:N3) -> 2015676
A4: Cost of Sales | B4: ='Hourly Customer'!$J$23*4 -> 53507.1 | C4: ='Hourly Customer'!$J$23*4 -> 53507.1 | D4: ='Hourly Customer'!$J$23*4 -> 53507.1 | E4: ='Hourly Customer'!$J$23*4 -> 53507.1 | F4: ='Hourly Customer'!$J$23*4 -> 53507.1 | G4: ='Hourly Customer'!$J$23*4 -> 53507.1 | H4: ='Hourly Customer'!$J$23*4 -> 53507.1 | I4: ='Hourly Customer'!$J$23*4 -> 53507.1 | ... N4: ='Hourly Customer'!$J$23*4 -> 53507.1 | O4: =SUM(B4:N4) -> 695592.3
A5: Labor | B5: ='Income Statement'!$D$15/13 -> 82016.281 | C5: ='Income Statement'!$D$15/13 -> 82016.281 | D5: ='Income Statement'!$D$15/13 -> 82016.281 | E5: ='Income Statement'!$D$15/13 -> 82016.281 | F5: ='Income Statement'!$D$15/13 -> 82016.281 | G5: ='Income Statement'!$D$15/13 -> 82016.281 | H5: ='Income Statement'!$D$15/13 -> 82016.281 | I5: ='Income Statement'!$D$15/13 -> 82016.281 | ... N5: ='Income Statement'!$D$15/13 -> 82016.281 | O5: =SUM(B5:N5) -> 1066211.7
A6: Prime Cost | B6: =B4+B5 -> 135523.38 | C6: =C4+C5 -> 135523.38 | D6: =D4+D5 -> 135523.38 | E6: =E4+E5 -> 135523.38 | F6: =F4+F5 -> 135523.38 | G6: =G4+G5 -> 135523.38 | H6: =H4+H5 -> 135523.38 | I6: =I4+I5 -> 135523.38 | ... N6: =N4+N5 -> 135523.38 | O6: =SUM(B6:N6) -> 1761804
A7: Other Controllable Expenses
A8: Total Operating Expenses | B8: ='Income Statement'!$C$29/13 -> 5312.0585 | C8: ='Income Statement'!$C$29/13 -> 5312.0585 | D8: ='Income Statement'!$C$29/13 -> 5312.0585 | E8: ='Income Statement'!$C$29/13 -> 5312.0585 | F8: ='Income Statement'!$C$29/13 -> 5312.0585 | G8: ='Income Statement'!$C$29/13 -> 5312.0585 | H8: ='Income Statement'!$C$29/13 -> 5312.0585 | I8: ='Income Statement'!$C$29/13 -> 5312.0585 | ... N8: ='Income Statement'!$C$29/13 -> 5312.0585 | O8: =SUM(B8:N8) -> 69056.76
A9: Total Marketing Expense | B9: ='Income Statement'!$C$34/13 -> 1192.3077 | C9: ='Income Statement'!$C$34/13 -> 1192.3077 | D9: ='Income Statement'!$C$34/13 -> 1192.3077 | E9: ='Income Statement'!$C$34/13 -> 1192.3077 | F9: ='Income Statement'!$C$34/13 -> 1192.3077 | G9: ='Income Statement'!$C$34/13 -> 1192.3077 | H9: ='Income Statement'!$C$34/13 -> 1192.3077 | I9: ='Income Statement'!$C$34/13 -> 1192.3077 | ... N9: ='Income Statement'!$C$34/13 -> 1192.3077 | O9: =SUM(B9:N9) -> 15500
A10: Total Energy Expenses | B10: ='Income Statement'!$C$40/13 -> 3307.6923 | C10: ='Income Statement'!$C$40/13 -> 3307.6923 | D10: ='Income Statement'!$C$40/13 -> 3307.6923 | E10: ='Income Statement'!$C$40/13 -> 3307.6923 | F10: ='Income Statement'!$C$40/13 -> 3307.6923 | G10: ='Income Statement'!$C$40/13 -> 3307.6923 | H10: ='Income Statement'!$C$40/13 -> 3307.6923 | I10: ='Income Statement'!$C$40/13 -> 3307.6923 | ... N10: ='Income Statement'!$C$40/13 -> 3307.6923 | O10: =SUM(B10:N10) -> 43000
A11: Total Administrative Expenses | B11: ='Income Statement'!$C$47/13 -> 4175.5514 | C11: ='Income Statement'!$C$47/13 -> 4175.5514 | D11: ='Income Statement'!$C$47/13 -> 4175.5514 | E11: ='Income Statement'!$C$47/13 -> 4175.5514 | F11: ='Income Statement'!$C$47/13 -> 4175.5514 | G11: ='Income Statement'!$C$47/13 -> 4175.5514 | H11: ='Income Statement'!$C$47/13 -> 4175.5514 | I11: ='Income Statement'!$C$47/13 -> 4175.5514 | ... N11: ='Income Statement'!$C$47/13 -> 4175.5514 | O11: =SUM(B11:N11) -> 54282.168
A12: Total Repair & Maintenance | B12: ='Income Statement'!$C$56/13 -> 2230.7692 | C12: ='Income Statement'!$C$56/13 -> 2230.7692 | D12: ='Income Statement'!$C$56/13 -> 2230.7692 | E12: ='Income Statement'!$C$56/13 -> 2230.7692 | F12: ='Income Statement'!$C$56/13 -> 2230.7692 | G12: ='Income Statement'!$C$56/13 -> 2230.7692 | H12: ='Income Statement'!$C$56/13 -> 2230.7692 | I12: ='Income Statement'!$C$56/13 -> 2230.7692 | ... N12: ='Income Statement'!$C$56/13 -> 2230.7692 | O12: =SUM(B12:N12) -> 29000
A13: Total Other Controllable Expenses | B13: =SUM(B8:B12) -> 16218.379 | C13: =SUM(C8:C12) -> 16218.379 | D13: =SUM(D8:D12) -> 16218.379 | E13: =SUM(E8:E12) -> 16218.379 | F13: =SUM(F8:F12) -> 16218.379 | G13: =SUM(G8:G12) -> 16218.379 | H13: =SUM(H8:H12) -> 16218.379 | I13: =SUM(I8:I12) -> 16218.379 | ... N13: =SUM(N8:N12) -> 16218.379 | O13: =SUM(B13:N13) -> 210838.93
A14: Controllable Income | B14: =B3-B6-B13 -> 3310.2397 | C14: =C3-C6-C13 -> 3310.2397 | D14: =D3-D6-D13 -> 3310.2397 | E14: =E3-E6-E13 -> 3310.2397 | F14: =F3-F6-F13 -> 3310.2397 | G14: =G3-G6-G13 -> 3310.2397 | H14: =H3-H6-H13 -> 3310.2397 | I14: =I3-I6-I13 -> 3310.2397 | ... N14: =N3-N6-N13 -> 3310.2397 | O14: =SUM(B14:N14) -> 43033.117
A15: Non-Controllable Expenses
A16: Lease Payment | B16: ='Income Statement'!$C$62/13 -> 1384.6154 | C16: ='Income Statement'!$C$62/13 -> 1384.6154 | D16: ='Income Statement'!$C$62/13 -> 1384.6154 | E16: ='Income Statement'!$C$62/13 -> 1384.6154 | F16: ='Income Statement'!$C$62/13 -> 1384.6154 | G16: ='Income Statement'!$C$62/13 -> 1384.6154 | H16: ='Income Statement'!$C$62/13 -> 1384.6154 | I16: ='Income Statement'!$C$62/13 -> 1384.6154 | ... N16: ='Income Statement'!$C$62/13 -> 1384.6154 | O16: =SUM(B16:N16) -> 18000
A17: Depreciation & Amortization | B17: ='Income Statement'!$C$63/13 -> 3834.9229 | C17: ='Income Statement'!$C$63/13 -> 3834.9229 | D17: ='Income Statement'!$C$63/13 -> 3834.9229 | E17: ='Income Statement'!$C$63/13 -> 3834.9229 | F17: ='Income Statement'!$C$63/13 -> 3834.9229 | G17: ='Income Statement'!$C$63/13 -> 3834.9229 | H17: ='Income Statement'!$C$63/13 -> 3834.9229 | I17: ='Income Statement'!$C$63/13 -> 3834.9229 | ... N17: ='Income Statement'!$C$63/13 -> 3834.9229 | O17: =SUM(B17:N17) -> 49853.998
A18: Total Non-controllable Expenses | B18: =SUM(B16:B17) -> 5219.5383 | C18: =SUM(C16:C17) -> 5219.5383 | D18: =SUM(D16:D17) -> 5219.5383 | E18: =SUM(E16:E17) -> 5219.5383 | F18: =SUM(F16:F17) -> 5219.5383 | G18: =SUM(G16:G17) -> 5219.5383 | H18: =SUM(H16:H17) -> 5219.5383 | I18: =SUM(I16:I17) -> 5219.5383 | ... N18: =SUM(N16:N17) -> 5219.5383 | O18: =SUM(B18:N18) -> 67853.998
A19: Restaurant Operating Income | B19: =B14-B18 -> -1909.2986 | C19: =C14-C18 -> -1909.2986 | D19: =D14-D18 -> -1909.2986 | E19: =E14-E18 -> -1909.2986 | F19: =F14-F18 -> -1909.2986 | G19: =G14-G18 -> -1909.2986 | H19: =H14-H18 -> -1909.2986 | I19: =I14-I18 -> -1909.2986 | ... N19: =N14-N18 -> -1909.2986 | O19: =SUM(B19:N19) -> -24820.881
A20: Interest Expense | B20: ='Income Statement'!$D$69/13 -> 1005.1779 | C20: ='Income Statement'!$D$69/13 -> 1005.1779 | D20: ='Income Statement'!$D$69/13 -> 1005.1779 | E20: ='Income Statement'!$D$69/13 -> 1005.1779 | F20: ='Income Statement'!$D$69/13 -> 1005.1779 | G20: ='Income Statement'!$D$69/13 -> 1005.1779 | H20: ='Income Statement'!$D$69/13 -> 1005.1779 | I20: ='Income Statement'!$D$69/13 -> 1005.1779 | ... N20: ='Income Statement'!$D$69/13 -> 1005.1779 | O20: =SUM(B20:N20) -> 13067.313
A21: Income Before Income Taxes | B21: =B19-B20 -> -2914.4765 | C21: =C19-C20 -> -2914.4765 | D21: =D19-D20 -> -2914.4765 | E21: =E19-E20 -> -2914.4765 | F21: =F19-F20 -> -2914.4765 | G21: =G19-G20 -> -2914.4765 | H21: =H19-H20 -> -2914.4765 | I21: =I19-I20 -> -2914.4765 | ... N21: =N19-N20 -> -2914.4765 | O21: =SUM(B21:N21) -> -37888.195

Sheet 10 year IS
A1: Pro Forma Income Statement – 10-year Forecast
B2: Year 1 | C2: Year 2 | D2: Year 3 | E2: Year 4 | F2: Year 5 | G2: Year 6 | H2: Year 7 | I2: Year 8 | J2: Year 9 | K2: Year 10
A3: Revenues | B3: =E3*0.6 -> 1209405.6 | C3: =E3*0.7 -> 1410973.2 | D3: =E3*0.85 -> 1713324.6 | E3: ='Monthly IS'!$O$3 -> 2015676 | F3: ='Monthly IS'!$O$3 -> 2015676 | G3: ='Monthly IS'!$O$3 -> 2015676 | H3: ='Monthly IS'!$O$3 -> 2015676 | I3: ='Monthly IS'!$O$3 -> 2015676 | J3: ='Monthly IS'!$O$3 -> 2015676 | K3: ='Monthly IS'!$O$3 -> 2015676
A4: Cost of Sales | B4: =E4*0.6 -> 417355.38 | C4: =E4*0.7 -> 486914.61 | D4: =E4*0.85 -> 591253.45 | E4: ='Monthly IS'!$O$4 -> 695592.3 | F4: ='Monthly IS'!$O$4 -> 695592.3 | G4: ='Monthly IS'!$O$4 -> 695592.3 | H4: ='Monthly IS'!$O$4 -> 695592.3 | I4: ='Monthly IS'!$O$4 -> 695592.3 | J4: ='Monthly IS'!$O$4 -> 695592.3 | K4: ='Monthly IS'!$O$4 -> 695592.3
A5: Labor | B5: =E5*0.8 -> 852969.32 | C5: =E5*0.85 -> 906279.91 | D5: =E5*0.9 -> 959590.49 | E5: ='Monthly IS'!$O$5 -> 1066211.7 | F5: ='Monthly IS'!$O$5 -> 1066211.7 | G5: ='Monthly IS'!$O$5 -> 1066211.7 | H5: ='Monthly IS'!$O$5 -> 1066211.7 | I5: ='Monthly IS'!$O$5 -> 1066211.7 | J5: ='Monthly IS'!$O$5 -> 1066211.7 | K5: ='Monthly IS'!$O$5 -> 1066211.7
A6: Prime Cost | B6: =B4+B5 -> 1270324.7 | C6: =C4+C5 -> 1393194.5 | D6: =D4+D5 -> 1550843.9 | E6: =E4+E5 -> 1761804 | F6: =F4+F5 -> 1761804 | G6: =G4+G5 -> 1761804 | H6: =H4+H5 -> 1761804 | I6: =I4+I5 -> 1761804 | ... K6: =K4+K5 -> 1761804
A7: Other Controllable Expenses
A8: Total Operating Expenses | B8: ='Monthly IS'!$O$8 -> 69056.76 | C8: ='Monthly IS'!$O$8 -> 69056.76 | D8: ='Monthly IS'!$O$8 -> 69056.76 | E8: ='Monthly IS'!$O$8 -> 69056.76 | F8: ='Monthly IS'!$O$8 -> 69056.76 | G8: ='Monthly IS'!$O$8 -> 69056.76 | H8: ='Monthly IS'!$O$8 -> 69056.76 | I8: ='Monthly IS'!$O$8 -> 69056.76 | ... K8: ='Monthly IS'!$O$8 -> 69056.76
A9: Total Marketing Expense | B9: ='Monthly IS'!$O$9 -> 15500 | C9: ='Monthly IS'!$O$9 -> 15500 | D9: ='Monthly IS'!$O$9 -> 15500 | E9: ='Monthly IS'!$O$9 -> 15500 | F9: ='Monthly IS'!$O$9 -> 15500 | G9: ='Monthly IS'!$O$9 -> 15500 | H9: ='Monthly IS'!$O$9 -> 15500 | I9: ='Monthly IS'!$O$9 -> 15500 | ... K9: ='Monthly IS'!$O$9 -> 15500
A10: Total Energy Expenses | B10: ='Monthly IS'!$O$10 -> 43000 | C10: ='Monthly IS'!$O$10 -> 43000 | D10: ='Monthly IS'!$O$10 -> 43000 | E10: ='Monthly IS'!$O$10 -> 43000 | F10: ='Monthly IS'!$O$10 -> 43000 | G10: ='Monthly IS'!$O$10 -> 43000 | H10: ='Monthly IS'!$O$10 -> 43000 | I10: ='Monthly IS'!$O$10 -> 43000 | ... K10: ='Monthly IS'!$O$10 -> 43000
A11: Total Administrative Expenses | B11: ='Monthly IS'!$O$11 -> 54282.168 | C11: ='Monthly IS'!$O$11 -> 54282.168 | D11: ='Monthly IS'!$O$11 -> 54282.168 | E11: ='Monthly IS'!$O$11 -> 54282.168 | F11: ='Monthly IS'!$O$11 -> 54282.168 | G11: ='Monthly IS'!$O$11 -> 54282.168 | H11: ='Monthly IS'!$O$11 -> 54282.168 | I11: ='Monthly IS'!$O$11 -> 54282.168 | ... K11: ='Monthly IS'!$O$11 -> 54282.168
A12: Total Repair & Maintenance | B12: ='Monthly IS'!$O$12 -> 29000 | C12: ='Monthly IS'!$O$12 -> 29000 | D12: ='Monthly IS'!$O$12 -> 29000 | E12: ='Monthly IS'!$O$12 -> 29000 | F12: ='Monthly IS'!$O$12 -> 29000 | G12: ='Monthly IS'!$O$12 -> 29000 | H12: ='Monthly IS'!$O$12 -> 29000 | I12: ='Monthly IS'!$O$12 -> 29000 | ... K12: ='Monthly IS'!$O$12 -> 29000
A13: Total Other Controllable Expenses | B13: =SUM(B8:B12) -> 210838.93 | C13: =SUM(C8:C12) -> 210838.93 | D13: =SUM(D8:D12) -> 210838.93 | E13: =SUM(E8:E12) -> 210838.93 | F13: =SUM(F8:F12) -> 210838.93 | G13: =SUM(G8:G12) -> 210838.93 | H13: =SUM(H8:H12) -> 210838.93 | I13: =SUM(I8:I12) -> 210838.93 | ... K13: =SUM(K8:K12) -> 210838.93
A14: Controllable Income | B14: =B3-B6-B13 -> -271758.03 | C14: =C3-C6-C13 -> -193060.24 | D14: =D3-D6-D13 -> -48358.273 | E14: =E3-E6-E13 -> 43033.117 | F14: =F3-F6-F13 -> 43033.117 | G14: =G3-G6-G13 -> 43033.117 | H14: =H3-H6-H13 -> 43033.117 | I14: =I3-I6-I13 -> 43033.117 | ... K14: =K3-K6-K13 -> 43033.117
A15: Non-Controllable Expenses
A16: Lease Payment | B16: ='Monthly IS'!$O$16 -> 18000 | C16: ='Monthly IS'!$O$16 -> 18000 | D16: ='Monthly IS'!$O$16 -> 18000 | E16: ='Monthly IS'!$O$16 -> 18000 | F16: ='Monthly IS'!$O$16 -> 18000 | G16: ='Monthly IS'!$O$16 -> 18000 | H16: ='Monthly IS'!$O$16 -> 18000 | I16: ='Monthly IS'!$O$16 -> 18000 | ... K16: ='Monthly IS'!$O$16 -> 18000
A17: Depreciation & Amortization | B17: ='Monthly IS'!$O$17 -> 49853.998 | C17: ='Monthly IS'!$O$17 -> 49853.998 | D17: ='Monthly IS'!$O$17 -> 49853.998 | E17: ='Monthly IS'!$O$17 -> 49853.998 | F17: ='Monthly IS'!$O$17 -> 49853.998 | G17: 0 | H17: 0 | I17: 0 | J17: 0 | K17: 0
A18: Total Non-controllable Expenses | B18: =SUM(B16:B17) -> 67853.998 | C18: =SUM(C16:C17) -> 67853.998 | D18: =SUM(D16:D17) -> 67853.998 | E18: =SUM(E16:E17) -> 67853.998 | F18: =SUM(F16:F17) -> 67853.998 | G18: =SUM(G16:G17) -> 18000 | H18: =SUM(H16:H17) -> 18000 | I18: =SUM(I16:I17) -> 18000 | ... K18: =SUM(K16:K17) -> 18000
A19: Restaurant Operating Income | B19: =B14-B18 -> -339612.03 | C19: =C14-C18 -> -260914.24 | D19: =D14-D18 -> -116212.27 | E19: =E14-E18 -> -24820.881 | F19: =F14-F18 -> -24820.881 | G19: =G14-G18 -> 25033.117 | H19: =H14-H18 -> 25033.117 | I19: =I14-I18 -> 25033.117 | ... K19: =K14-K18 -> 25033.117
A20: Interest Expense | B20: ='Loan Amortization'!D7 -> 16576.454 | C20: ='Loan Amortization'!D8 -> 15511.149 | D20: ='Loan Amortization'!D9 -> 14344.641 | E20: ='Loan Amortization'!D10 -> 13067.313 | F20: ='Loan Amortization'!D11 -> 11668.64 | G20: ='Loan Amortization'!D12 -> 10137.093 | H20: ='Loan Amortization'!D13 -> 8460.0484 | I20: ='Loan Amortization'!D14 -> 6623.6849 | J20: ='Loan Amortization'!D15 -> 4612.8668 | K20: ='Loan Amortization'!D16 -> 2411.0211
A21: Income Before Income Taxes | B21: =B19-B20 -> -356188.48 | C21: =C19-C20 -> -276425.39 | D21: =D19-D20 -> -130556.91 | E21: =E19-E20 -> -37888.195 | F21: =F19-F20 -> -36489.521 | G21: =G19-G20 -> 14896.024 | H21: =H19-H20 -> 16573.068 | I21: =I19-I20 -> 18409.432 | ... K21: =K19-K20 -> 22622.096
A22: Income Tax Expense (30%) | B22: =B21*0.3 -> -106856.55 | C22: =C21*0.3 -> -82927.618 | D22: =D21*0.3 -> -39167.073 | E22: =E21*0.3 -> -11366.458 | F22: =F21*0.3 -> -10946.856 | G22: =G21*0.3 -> 4468.8072 | H22: =H21*0.3 -> 4971.9205 | I22: =I21*0.3 -> 5522.8296 | ... K22: =K21*0.3 -> 6786.6287
A23: Net Income | B23: =B21-B22 -> -249331.94 | C23: =C21-C22 -> -193497.77 | D23: =D21-D22 -> -91389.838 | E23: =E21-E22 -> -26521.736 | F23: =F21-F22 -> -25542.665 | G23: =G21-G22 -> 10427.217 | H23: =H21-H22 -> 11601.148 | I23: =I21-I22 -> 12886.602 | ... K23: =K21-K22 -> 15835.467

Sheet Loan Amortization
A1: Loan Amortization Table
A2: Loan amount (PV) | B2: =Preopening!C48 -> 174488.99 | C2: Interest Rate | D2: 0.095 | E2: Term | F2: 10
A3: Payment | B3: =PMT(D2,F2,B2) -> -27790.19 | C3: PVIFA | F3: =IFERROR(B2/B3,0) -> -6.278798
A5: Term (years) | B5: Payment | C5: Rate | D5: Interest $ | E5: Principal $ | F5: Balance
A6: 0 | F6: =B2 -> 174488.99
A7: =A6+1 -> 1 | B7: =-B3 -> 27790.19 | C7: =$D$2 -> 0.095 | D7: =C7*F6 -> 16576.454 | E7: =B7-D7 -> 11213.736 | F7: =F6-E7 -> 163275.26
A8: =A7+1 -> 2 | B8: =$B$7 -> 27790.19 | C8: =$D$2 -> 0.095 | D8: =C8*F7 -> 15511.149 | E8: =B8-D8 -> 12279.041 | F8: =F7-E8 -> 150996.22
A9: =A8+1 -> 3 | B9: =$B$7 -> 27790.19 | C9: =$D$2 -> 0.095 | D9: =C9*F8 -> 14344.641 | E9: =B9-D9 -> 13445.55 | F9: =F8-E9 -> 137550.67
A10: =A9+1 -> 4 | B10: =$B$7 -> 27790.19 | C10: =$D$2 -> 0.095 | D10: =C10*F9 -> 13067.313 | E10: =B10-D10 -> 14722.877 | F10: =F9-E10 -> 122827.79
A11: =A10+1 -> 5 | B11: =$B$7 -> 27790.19 | C11: =$D$2 -> 0.095 | D11: =C11*F10 -> 11668.64 | E11: =B11-D11 -> 16121.55 | F11: =F10-E11 -> 106706.24
A12: =A11+1 -> 6 | B12: =$B$7 -> 27790.19 | C12: =$D$2 -> 0.095 | D12: =C12*F11 -> 10137.093 | E12: =B12-D12 -> 17653.098 | F12: =F11-E12 -> 89053.141
A13: =A12+1 -> 7 | B13: =$B$7 -> 27790.19 | C13: =$D$2 -> 0.095 | D13: =C13*F12 -> 8460.0484 | E13: =B13-D13 -> 19330.142 | F13: =F12-E13 -> 69722.998
A14: =A13+1 -> 8 | B14: =$B$7 -> 27790.19 | C14: =$D$2 -> 0.095 | D14: =C14*F13 -> 6623.6849 | E14: =B14-D14 -> 21166.506 | F14: =F13-E14 -> 48556.493
A15: =A14+1 -> 9 | B15: =$B$7 -> 27790.19 | C15: =$D$2 -> 0.095 | D15: =C15*F14 -> 4612.8668 | E15: =B15-D15 -> 23177.324 | F15: =F14-E15 -> 25379.169
A16: =A15+1 -> 10 | B16: =$B$7 -> 27790.19 | C16: =$D$2 -> 0.095 | D16: =C16*F15 -> 2411.0211 | E16: =B16-D16 -> 25379.169 | F16: =F15-E16 -> -1.0913936e-10
A17: Total | B17: =SUM(B7:B16) -> 277901.9 | D17: =SUM(D7:D16) -> 103412.91 | E17: =B17-D17 -> 174488.99

Sheet Cash Budget
A1: Cash Balance Projection
C2: January (31 days) | H2: February (28 days) | M2: March (31 days) | R2: April (30 days) | W2: May (31 days) | AB2: June (30 days) | AG2: July (31 days) | AL2: August (31 days) | AQ2: September (30 days) | AV2: October (31 days) | BA2: November (30 days) | BF2: December (31 days)
A3: Cash Sources & Uses | C3: Week | E3: in | F3: out | G3: Balance | H3: Date | J3: in | K3: out | L3: Balance | M3: Date | O3: in | P3: out | Q3: Balance | R3: Date | T3: in | U3: out | V3: Balance | W3: Date | Y3: in | Z3: out | AA3: Balance | AB3: Date | AD3: in | AE3: out | AF3: Balance | AG3: Date | AI3: in | AJ3: out | AK3: Balance | AL3: Date | AN3: in | AO3: out | AP3: Balance | AQ3: Date | AS3: in | AT3: out | AU3: Balance | AV3: Date | AX3: in | AY3: out | AZ3: Balance | BA3: Date | BC3: in | BD3: out | BE3: Balance | BF3: Date | BH3: in | BI3: out | BJ3: Balance
A4: Sales | B4: Expenditure | E4: Beginning Cash | G4: 20000 | J4: cash infusion | L4: =G36 -> #REF! | O4: cash infusion | Q4: =L36 -> #REF! | T4: cash infusion | V4: =Q36 -> #REF! | Y4: cash infusion | AA4: =V36 -> #REF! | AD4: cash infusion | AF4: =AA36 -> #REF! | AI4: cash infusion | AK4: =AF36 -> #REF! | AN4: cash infusion | AP4: =AK36 -> #REF! | AS4: cash infusion | AU4: =AP36 -> #REF! | AX4: cash infusion | AZ4: =AU36 -> #REF! | BC4: cash infusion | BE4: =AZ36 -> #REF! | BH4: cash infusion | BJ4: =BE36 -> #REF!
A5: Daily Sales | B5: Inventory prchs | C5: Week 1 | D5: 1 | E5: ='Hourly Customer'!$D$29 -> 0 | F5: ='Monthly IS'!#REF! -> #REF! | G5: =G4+E5-F5 -> #REF! | H5: Week 1 | I5: 1 | J5: ='Hourly Customer'!$D$29 -> 0 | K5: ='Monthly IS'!#REF! -> #REF! | L5: =L4+J5-K5 -> #REF! | M5: Week 1 | N5: 1 | O5: ='Hourly Customer'!$D$29 -> 0 | P5: ='Monthly IS'!#REF! -> #REF! | Q5: =Q4+O5-P5 -> #REF! | R5: Week 1 | S5: 1 | T5: ='Hourly Customer'!$D$29 -> 0 | U5: ='Monthly IS'!#REF! -> #REF! | V5: =V4+T5-U5 -> #REF! | W5: Week 1 | X5: 1 | Y5: ='Hourly Customer'!$D$29 -> 0 | Z5: ='Monthly IS'!#REF! -> #REF! | AA5: =AA4+Y5-Z5 -> #REF! | AB5: Week 1 | AC5: 1 | AD5: ='Hourly Customer'!$D$29 -> 0 | AE5: ='Monthly IS'!#REF! -> #REF! | AF5: =AF4+AD5-AE5 -> #REF! | AG5: Week 1 | AH5: 1 | AI5: ='Hourly Customer'!$D$29 -> 0 | AJ5: ='Monthly IS'!#REF! -> #REF! | AK5: =AK4+AI5-AJ5 -> #REF! | AL5: Week 1 | AM5: 1 | AN5: ='Hourly Customer'!$D$29 -> 0 | AO5: ='Monthly IS'!#REF! -> #REF! | AP5: =AP4+AN5-AO5 -> #REF! | AQ5: Week 1 | AR5: 1 | AS5: ='Hourly Customer'!$D$29 -> 0 | AT5: ='Monthly IS'!#REF! -> #REF! | AU5: =AU4+AS5-AT5 -> #REF! | AV5: Week 1 | AW5: 1 | AX5: ='Hourly Customer'!$D$29 -> 0 | AY5: ='Monthly IS'!#REF! -> #REF! | AZ5: =AZ4+AX5-AY5 -> #REF! | BA5: Week 1 | BB5: 1 | BC5: ='Hourly Customer'!$D$29 -> 0 | BD5: ='Monthly IS'!#REF! -> #REF! | BE5: =BE4+BC5-BD5 -> #REF! | BF5: Week 1 | BG5: 1 | BH5: ='Hourly Customer'!$D$29 -> 0 | BI5: ='Monthly IS'!#REF! -> #REF! | BJ5: =BJ4+BH5-BI5 -> #REF!
A6: Daily Sales | D6: 2 | E6: ='Hourly Customer'!$D$29 -> 0 | G6: =G5+E6-F6 -> #REF! | I6: 2 | J6: ='Hourly Customer'!$D$29 -> 0 | L6: =L5+J6-K6 -> #REF! | N6: 2 | O6: ='Hourly Customer'!$D$29 -> 0 | Q6: =Q5+O6-P6 -> #REF! | S6: 2 | T6: ='Hourly Customer'!$D$29 -> 0 | V6: =V5+T6-U6 -> #REF! | X6: 2 | Y6: ='Hourly Customer'!$D$29 -> 0 | AA6: =AA5+Y6-Z6 -> #REF! | AC6: 2 | AD6: ='Hourly Customer'!$D$29 -> 0 | AF6: =AF5+AD6-AE6 -> #REF! | AH6: 2 | AI6: ='Hourly Customer'!$D$29 -> 0 | AK6: =AK5+AI6-AJ6 -> #REF! | AM6: 2 | AN6: ='Hourly Customer'!$D$29 -> 0 | AP6: =AP5+AN6-AO6 -> #REF! | AR6: 2 | AS6: ='Hourly Customer'!$D$29 -> 0 | AU6: =AU5+AS6-AT6 -> #REF! | AW6: 2 | AX6: ='Hourly Customer'!$D$29 -> 0 | AZ6: =AZ5+AX6-AY6 -> #REF! | BB6: 2 | BC6: ='Hourly Customer'!$D$29 -> 0 | BE6: =BE5+BC6-BD6 -> #REF! | BG6: 2 | BH6: ='Hourly Customer'!$D$29 -> 0 | BJ6: =BJ5+BH6-BI6 -> #REF!
A7: Daily Sales | D7: 3 | E7: ='Hourly Customer'!$D$29 -> 0 | G7: =G6+E7-F7 -> #REF! | I7: 3 | J7: ='Hourly Customer'!$D$29 -> 0 | L7: =L6+J7-K7 -> #REF! | N7: 3 | O7: ='Hourly Customer'!$D$29 -> 0 | Q7: =Q6+O7-P7 -> #REF! | S7: 3 | T7: ='Hourly Customer'!$D$29 -> 0 | V7: =V6+T7-U7 -> #REF! | X7: 3 | Y7: ='Hourly Customer'!$D$29 -> 0 | AA7: =AA6+Y7-Z7 -> #REF! | AC7: 3 | AD7: ='Hourly Customer'!$D$29 -> 0 | AF7: =AF6+AD7-AE7 -> #REF! | AH7: 3 | AI7: ='Hourly Customer'!$D$29 -> 0 | AK7: =AK6+AI7-AJ7 -> #REF! | AM7: 3 | AN7: ='Hourly Customer'!$D$29 -> 0 | AP7: =AP6+AN7-AO7 -> #REF! | AR7: 3 | AS7: ='Hourly Customer'!$D$29 -> 0 | AU7: =AU6+AS7-AT7 -> #REF! | AW7: 3 | AX7: ='Hourly Customer'!$D$29 -> 0 | AZ7: =AZ6+AX7-AY7 -> #REF! | BB7: 3 | BC7: ='Hourly Customer'!$D$29 -> 0 | BE7: =BE6+BC7-BD7 -> #REF! | BG7: 3 | BH7: ='Hourly Customer'!$D$29 -> 0 | BJ7: =BJ6+BH7-BI7 -> #REF!
A8: Daily Sales | D8: 4 | E8: ='Hourly Customer'!$D$29 -> 0 | G8: =G7+E8-F8 -> #REF! | I8: 4 | J8: ='Hourly Customer'!$D$29 -> 0 | L8: =L7+J8-K8 -> #REF! | N8: 4 | O8: ='Hourly Customer'!$D$29 -> 0 | Q8: =Q7+O8-P8 -> #REF! | S8: 4 | T8: ='Hourly Customer'!$D$29 -> 0 | V8: =V7+T8-U8 -> #REF! | X8: 4 | Y8: ='Hourly Customer'!$D$29 -> 0 | AA8: =AA7+Y8-Z8 -> #REF! | AC8: 4 | AD8: ='Hourly Customer'!$D$29 -> 0 | AF8: =AF7+AD8-AE8 -> #REF! | AH8: 4 | AI8: ='Hourly Customer'!$D$29 -> 0 | AK8: =AK7+AI8-AJ8 -> #REF! | AM8: 4 | AN8: ='Hourly Customer'!$D$29 -> 0 | AP8: =AP7+AN8-AO8 -> #REF! | AR8: 4 | AS8: ='Hourly Customer'!$D$29 -> 0 | AU8: =AU7+AS8-AT8 -> #REF! | AW8: 4 | AX8: ='Hourly Customer'!$D$29 -> 0 | AZ8: =AZ7+AX8-AY8 -> #REF! | BB8: 4 | BC8: ='Hourly Customer'!$D$29 -> 0 | BE8: =BE7+BC8-BD8 -> #REF! | BG8: 4 | BH8: ='Hourly Customer'!$D$29 -> 0 | BJ8: =BJ7+BH8-BI8 -> #REF!
A9: Daily Sales | B9: Payroll expenses | D9: 5 | E9: ='Hourly Customer'!$D$29 -> 0 | F9: ='Monthly IS'!#REF! -> #REF! | G9: =G8+E9-F9 -> #REF! | I9: 5 | J9: ='Hourly Customer'!$D$29 -> 0 | K9: ='Monthly IS'!#REF! -> #REF! | L9: =L8+J9-K9 -> #REF! | N9: 5 | O9: ='Hourly Customer'!$D$29 -> 0 | P9: ='Monthly IS'!#REF! -> #REF! | Q9: =Q8+O9-P9 -> #REF! | S9: 5 | T9: ='Hourly Customer'!$D$29 -> 0 | U9: ='Monthly IS'!#REF! -> #REF! | V9: =V8+T9-U9 -> #REF! | X9: 5 | Y9: ='Hourly Customer'!$D$29 -> 0 | Z9: ='Monthly IS'!#REF! -> #REF! | AA9: =AA8+Y9-Z9 -> #REF! | AC9: 5 | AD9: ='Hourly Customer'!$D$29 -> 0 | AE9: ='Monthly IS'!#REF! -> #REF! | AF9: =AF8+AD9-AE9 -> #REF! | AH9: 5 | AI9: ='Hourly Customer'!$D$29 -> 0 | AJ9: ='Monthly IS'!#REF! -> #REF! | AK9: =AK8+AI9-AJ9 -> #REF! | AM9: 5 | AN9: ='Hourly Customer'!$D$29 -> 0 | AO9: ='Monthly IS'!#REF! -> #REF! | AP9: =AP8+AN9-AO9 -> #REF! | AR9: 5 | AS9: ='Hourly Customer'!$D$29 -> 0 | AT9: ='Monthly IS'!#REF! -> #REF! | AU9: =AU8+AS9-AT9 -> #REF! | AW9: 5 | AX9: ='Hourly Customer'!$D$29 -> 0 | AY9: ='Monthly IS'!#REF! -> #REF! | AZ9: =AZ8+AX9-AY9 -> #REF! | BB9: 5 | BC9: ='Hourly Customer'!$D$29 -> 0 | BD9: ='Monthly IS'!#REF! -> #REF! | BE9: =BE8+BC9-BD9 -> #REF! | BG9: 5 | BH9: ='Hourly Customer'!$D$29 -> 0 | BI9: ='Monthly IS'!#REF! -> #REF! | BJ9: =BJ8+BH9-BI9 -> #REF!
A10: Daily Sales | D10: 6 | E10: ='Hourly Customer'!$D$29 -> 0 | G10: =G9+E10-F10 -> #REF! | I10: 6 | J10: ='Hourly Customer'!$D$29 -> 0 | L10: =L9+J10-K10 -> #REF! | N10: 6 | O10: ='Hourly Customer'!$D$29 -> 0 | Q10: =Q9+O10-P10 -> #REF! | S10: 6 | T10: ='Hourly Customer'!$D$29 -> 0 | V10: =V9+T10-U10 -> #REF! | X10: 6 | Y10: ='Hourly Customer'!$D$29 -> 0 | AA10: =AA9+Y10-Z10 -> #REF! | AC10: 6 | AD10: ='Hourly Customer'!$D$29 -> 0 | AF10: =AF9+AD10-AE10 -> #REF! | AH10: 6 | AI10: ='Hourly Customer'!$D$29 -> 0 | AK10: =AK9+AI10-AJ10 -> #REF! | AM10: 6 | AN10: ='Hourly Customer'!$D$29 -> 0 | AP10: =AP9+AN10-AO10 -> #REF! | AR10: 6 | AS10: ='Hourly Customer'!$D$29 -> 0 | AU10: =AU9+AS10-AT10 -> #REF! | AW10: 6 | AX10: ='Hourly Customer'!$D$29 -> 0 | AZ10: =AZ9+AX10-AY10 -> #REF! | BB10: 6 | BC10: ='Hourly Customer'!$D$29 -> 0 | BE10: =BE9+BC10-BD10 -> #REF! | BG10: 6 | BH10: ='Hourly Customer'!$D$29 -> 0 | BJ10: =BJ9+BH10-BI10 -> #REF!
A11: Daily Sales | D11: 7 | E11: ='Hourly Customer'!$D$29 -> 0 | G11: =G10+E11-F11 -> #REF! | I11: 7 | J11: ='Hourly Customer'!$D$29 -> 0 | L11: =L10+J11-K11 -> #REF! | N11: 7 | O11: ='Hourly Customer'!$D$29 -> 0 | Q11: =Q10+O11-P11 -> #REF! | S11: 7 | T11: ='Hourly Customer'!$D$29 -> 0 | V11: =V10+T11-U11 -> #REF! | X11: 7 | Y11: ='Hourly Customer'!$D$29 -> 0 | AA11: =AA10+Y11-Z11 -> #REF! | AC11: 7 | AD11: ='Hourly Customer'!$D$29 -> 0 | AF11: =AF10+AD11-AE11 -> #REF! | AH11: 7 | AI11: ='Hourly Customer'!$D$29 -> 0 | AK11: =AK10+AI11-AJ11 -> #REF! | AM11: 7 | AN11: ='Hourly Customer'!$D$29 -> 0 | AP11: =AP10+AN11-AO11 -> #REF! | AR11: 7 | AS11: ='Hourly Customer'!$D$29 -> 0 | AU11: =AU10+AS11-AT11 -> #REF! | AW11: 7 | AX11: ='Hourly Customer'!$D$29 -> 0 | AZ11: =AZ10+AX11-AY11 -> #REF! | BB11: 7 | BC11: ='Hourly Customer'!$D$29 -> 0 | BE11: =BE10+BC11-BD11 -> #REF! | BG11: 7 | BH11: ='Hourly Customer'!$D$29 -> 0 | BJ11: =BJ10+BH11-BI11 -> #REF!
A12: Daily Sales | B12: Operating | C12: Week 2 | D12: 8 | E12: ='Hourly Customer'!$D$29 -> 0 | F12: ='Monthly IS'!#REF! -> #REF! | G12: =G11+E12-F12 -> #REF! | H12: Week 2 | I12: 8 | J12: ='Hourly Customer'!$D$29 -> 0 | K12: ='Monthly IS'!#REF! -> #REF! | L12: =L11+J12-K12 -> #REF! | M12: Week 2 | N12: 8 | O12: ='Hourly Customer'!$D$29 -> 0 | P12: ='Monthly IS'!#REF! -> #REF! | Q12: =Q11+O12-P12 -> #REF! | R12: Week 2 | S12: 8 | T12: ='Hourly Customer'!$D$29 -> 0 | U12: ='Monthly IS'!#REF! -> #REF! | V12: =V11+T12-U12 -> #REF! | W12: Week 2 | X12: 8 | Y12: ='Hourly Customer'!$D$29 -> 0 | Z12: ='Monthly IS'!#REF! -> #REF! | AA12: =AA11+Y12-Z12 -> #REF! | AB12: Week 2 | AC12: 8 | AD12: ='Hourly Customer'!$D$29 -> 0 | AE12: ='Monthly IS'!#REF! -> #REF! | AF12: =AF11+AD12-AE12 -> #REF! | AG12: Week 2 | AH12: 8 | AI12: ='Hourly Customer'!$D$29 -> 0 | AJ12: ='Monthly IS'!#REF! -> #REF! | AK12: =AK11+AI12-AJ12 -> #REF! | AL12: Week 2 | AM12: 8 | AN12: ='Hourly Customer'!$D$29 -> 0 | AO12: ='Monthly IS'!#REF! -> #REF! | AP12: =AP11+AN12-AO12 -> #REF! | AQ12: Week 2 | AR12: 8 | AS12: ='Hourly Customer'!$D$29 -> 0 | AT12: ='Monthly IS'!#REF! -> #REF! | AU12: =AU11+AS12-AT12 -> #REF! | AV12: Week 2 | AW12: 8 | AX12: ='Hourly Customer'!$D$29 -> 0 | AY12: ='Monthly IS'!#REF! -> #REF! | AZ12: =AZ11+AX12-AY12 -> #REF! | BA12: Week 2 | BB12: 8 | BC12: ='Hourly Customer'!$D$29 -> 0 | BD12: ='Monthly IS'!#REF! -> #REF! | BE12: =BE11+BC12-BD12 -> #REF! | BF12: Week 2 | BG12: 8 | BH12: ='Hourly Customer'!$D$29 -> 0 | BI12: ='Monthly IS'!#REF! -> #REF! | BJ12: =BJ11+BH12-BI12 -> #REF!
A13: Daily Sales | D13: 9 | E13: ='Hourly Customer'!$D$29 -> 0 | G13: =G12+E13-F13 -> #REF! | I13: 9 | J13: ='Hourly Customer'!$D$29 -> 0 | L13: =L12+J13-K13 -> #REF! | N13: 9 | O13: ='Hourly Customer'!$D$29 -> 0 | Q13: =Q12+O13-P13 -> #REF! | S13: 9 | T13: ='Hourly Customer'!$D$29 -> 0 | V13: =V12+T13-U13 -> #REF! | X13: 9 | Y13: ='Hourly Customer'!$D$29 -> 0 | AA13: =AA12+Y13-Z13 -> #REF! | AC13: 9 | AD13: ='Hourly Customer'!$D$29 -> 0 | AF13: =AF12+AD13-AE13 -> #REF! | AH13: 9 | AI13: ='Hourly Customer'!$D$29 -> 0 | AK13: =AK12+AI13-AJ13 -> #REF! | AM13: 9 | AN13: ='Hourly Customer'!$D$29 -> 0 | AP13: =AP12+AN13-AO13 -> #REF! | AR13: 9 | AS13: ='Hourly Customer'!$D$29 -> 0 | AU13: =AU12+AS13-AT13 -> #REF! | AW13: 9 | AX13: ='Hourly Customer'!$D$29 -> 0 | AZ13: =AZ12+AX13-AY13 -> #REF! | BB13: 9 | BC13: ='Hourly Customer'!$D$29 -> 0 | BE13: =BE12+BC13-BD13 -> #REF! | BG13: 9 | BH13: ='Hourly Customer'!$D$29 -> 0 | BJ13: =BJ12+BH13-BI13 -> #REF!
A14: Daily Sales | D14: 10 | E14: ='Hourly Customer'!$D$29 -> 0 | G14: =G13+E14-F14 -> #REF! | I14: 10 | J14: ='Hourly Customer'!$D$29 -> 0 | L14: =L13+J14-K14 -> #REF! | N14: 10 | O14: ='Hourly Customer'!$D$29 -> 0 | Q14: =Q13+O14-P14 -> #REF! | S14: 10 | T14: ='Hourly Customer'!$D$29 -> 0 | V14: =V13+T14-U14 -> #REF! | X14: 10 | Y14: ='Hourly Customer'!$D$29 -> 0 | AA14: =AA13+Y14-Z14 -> #REF! | AC14: 10 | AD14: ='Hourly Customer'!$D$29 -> 0 | AF14: =AF13+AD14-AE14 -> #REF! | AH14: 10 | AI14: ='Hourly Customer'!$D$29 -> 0 | AK14: =AK13+AI14-AJ14 -> #REF! | AM14: 10 | AN14: ='Hourly Customer'!$D$29 -> 0 | AP14: =AP13+AN14-AO14 -> #REF! | AR14: 10 | AS14: ='Hourly Customer'!$D$29 -> 0 | AU14: =AU13+AS14-AT14 -> #REF! | AW14: 10 | AX14: ='Hourly Customer'!$D$29 -> 0 | AZ14: =AZ13+AX14-AY14 -> #REF! | BB14: 10 | BC14: ='Hourly Customer'!$D$29 -> 0 | BE14: =BE13+BC14-BD14 -> #REF! | BG14: 10 | BH14: ='Hourly Customer'!$D$29 -> 0 | BJ14: =BJ13+BH14-BI14 -> #REF!
A15: Daily Sales | B15: Marketing | D15: 11 | E15: ='Hourly Customer'!$D$29 -> 0 | F15: ='Monthly IS'!#REF! -> #REF! | G15: =G14+E15-F15 -> #REF! | I15: 11 | J15: ='Hourly Customer'!$D$29 -> 0 | K15: ='Monthly IS'!#REF! -> #REF! | L15: =L14+J15-K15 -> #REF! | N15: 11 | O15: ='Hourly Customer'!$D$29 -> 0 | P15: ='Monthly IS'!#REF! -> #REF! | Q15: =Q14+O15-P15 -> #REF! | S15: 11 | T15: ='Hourly Customer'!$D$29 -> 0 | U15: ='Monthly IS'!#REF! -> #REF! | V15: =V14+T15-U15 -> #REF! | X15: 11 | Y15: ='Hourly Customer'!$D$29 -> 0 | Z15: ='Monthly IS'!#REF! -> #REF! | AA15: =AA14+Y15-Z15 -> #REF! | AC15: 11 | AD15: ='Hourly Customer'!$D$29 -> 0 | AE15: ='Monthly IS'!#REF! -> #REF! | AF15: =AF14+AD15-AE15 -> #REF! | AH15: 11 | AI15: ='Hourly Customer'!$D$29 -> 0 | AJ15: ='Monthly IS'!#REF! -> #REF! | AK15: =AK14+AI15-AJ15 -> #REF! | AM15: 11 | AN15: ='Hourly Customer'!$D$29 -> 0 | AO15: ='Monthly IS'!#REF! -> #REF! | AP15: =AP14+AN15-AO15 -> #REF! | AR15: 11 | AS15: ='Hourly Customer'!$D$29 -> 0 | AT15: ='Monthly IS'!#REF! -> #REF! | AU15: =AU14+AS15-AT15 -> #REF! | AW15: 11 | AX15: ='Hourly Customer'!$D$29 -> 0 | AY15: ='Monthly IS'!#REF! -> #REF! | AZ15: =AZ14+AX15-AY15 -> #REF! | BB15: 11 | BC15: ='Hourly Customer'!$D$29 -> 0 | BD15: ='Monthly IS'!#REF! -> #REF! | BE15: =BE14+BC15-BD15 -> #REF! | BG15: 11 | BH15: ='Hourly Customer'!$D$29 -> 0 | BI15: ='Monthly IS'!#REF! -> #REF! | BJ15: =BJ14+BH15-BI15 -> #REF!
A16: Daily Sales | D16: 12 | E16: ='Hourly Customer'!$D$29 -> 0 | G16: =G15+E16-F16 -> #REF! | I16: 12 | J16: ='Hourly Customer'!$D$29 -> 0 | L16: =L15+J16-K16 -> #REF! | N16: 12 | O16: ='Hourly Customer'!$D$29 -> 0 | Q16: =Q15+O16-P16 -> #REF! | S16: 12 | T16: ='Hourly Customer'!$D$29 -> 0 | V16: =V15+T16-U16 -> #REF! | X16: 12 | Y16: ='Hourly Customer'!$D$29 -> 0 | AA16: =AA15+Y16-Z16 -> #REF! | AC16: 12 | AD16: ='Hourly Customer'!$D$29 -> 0 | AF16: =AF15+AD16-AE16 -> #REF! | AH16: 12 | AI16: ='Hourly Customer'!$D$29 -> 0 | AK16: =AK15+AI16-AJ16 -> #REF! | AM16: 12 | AN16: ='Hourly Customer'!$D$29 -> 0 | AP16: =AP15+AN16-AO16 -> #REF! | AR16: 12 | AS16: ='Hourly Customer'!$D$29 -> 0 | AU16: =AU15+AS16-AT16 -> #REF! | AW16: 12 | AX16: ='Hourly Customer'!$D$29 -> 0 | AZ16: =AZ15+AX16-AY16 -> #REF! | BB16: 12 | BC16: ='Hourly Customer'!$D$29 -> 0 | BE16: =BE15+BC16-BD16 -> #REF! | BG16: 12 | BH16: ='Hourly Customer'!$D$29 -> 0 | BJ16: =BJ15+BH16-BI16 -> #REF!
A17: Daily Sales | D17: 13 | E17: ='Hourly Customer'!$D$29 -> 0 | G17: =G16+E17-F17 -> #REF! | I17: 13 | J17: ='Hourly Customer'!$D$29 -> 0 | L17: =L16+J17-K17 -> #REF! | N17: 13 | O17: ='Hourly Customer'!$D$29 -> 0 | Q17: =Q16+O17-P17 -> #REF! | S17: 13 | T17: ='Hourly Customer'!$D$29 -> 0 | V17: =V16+T17-U17 -> #REF! | X17: 13 | Y17: ='Hourly Customer'!$D$29 -> 0 | AA17: =AA16+Y17-Z17 -> #REF! | AC17: 13 | AD17: ='Hourly Customer'!$D$29 -> 0 | AF17: =AF16+AD17-AE17 -> #REF! | AH17: 13 | AI17: ='Hourly Customer'!$D$29 -> 0 | AK17: =AK16+AI17-AJ17 -> #REF! | AM17: 13 | AN17: ='Hourly Customer'!$D$29 -> 0 | AP17: =AP16+AN17-AO17 -> #REF! | AR17: 13 | AS17: ='Hourly Customer'!$D$29 -> 0 | AU17: =AU16+AS17-AT17 -> #REF! | AW17: 13 | AX17: ='Hourly Customer'!$D$29 -> 0 | AZ17: =AZ16+AX17-AY17 -> #REF! | BB17: 13 | BC17: ='Hourly Customer'!$D$29 -> 0 | BE17: =BE16+BC17-BD17 -> #REF! | BG17: 13 | BH17: ='Hourly Customer'!$D$29 -> 0 | BJ17: =BJ16+BH17-BI17 -> #REF!
A18: Daily Sales | B18: Energy | D18: 14 | E18: ='Hourly Customer'!$D$29 -> 0 | F18: ='Monthly IS'!#REF! -> #REF! | G18: =G17+E18-F18 -> #REF! | I18: 14 | J18: ='Hourly Customer'!$D$29 -> 0 | K18: ='Monthly IS'!#REF! -> #REF! | L18: =L17+J18-K18 -> #REF! | N18: 14 | O18: ='Hourly Customer'!$D$29 -> 0 | P18: ='Monthly IS'!#REF! -> #REF! | Q18: =Q17+O18-P18 -> #REF! | S18: 14 | T18: ='Hourly Customer'!$D$29 -> 0 | U18: ='Monthly IS'!#REF! -> #REF! | V18: =V17+T18-U18 -> #REF! | X18: 14 | Y18: ='Hourly Customer'!$D$29 -> 0 | Z18: ='Monthly IS'!#REF! -> #REF! | AA18: =AA17+Y18-Z18 -> #REF! | AC18: 14 | AD18: ='Hourly Customer'!$D$29 -> 0 | AE18: ='Monthly IS'!#REF! -> #REF! | AF18: =AF17+AD18-AE18 -> #REF! | AH18: 14 | AI18: ='Hourly Customer'!$D$29 -> 0 | AJ18: ='Monthly IS'!#REF! -> #REF! | AK18: =AK17+AI18-AJ18 -> #REF! | AM18: 14 | AN18: ='Hourly Customer'!$D$29 -> 0 | AO18: ='Monthly IS'!#REF! -> #REF! | AP18: =AP17+AN18-AO18 -> #REF! | AR18: 14 | AS18: ='Hourly Customer'!$D$29 -> 0 | AT18: ='Monthly IS'!#REF! -> #REF! | AU18: =AU17+AS18-AT18 -> #REF! | AW18: 14 | AX18: ='Hourly Customer'!$D$29 -> 0 | AY18: ='Monthly IS'!#REF! -> #REF! | AZ18: =AZ17+AX18-AY18 -> #REF! | BB18: 14 | BC18: ='Hourly Customer'!$D$29 -> 0 | BD18: ='Monthly IS'!#REF! -> #REF! | BE18: =BE17+BC18-BD18 -> #REF! | BG18: 14 | BH18: ='Hourly Customer'!$D$29 -> 0 | BI18: ='Monthly IS'!#REF! -> #REF! | BJ18: =BJ17+BH18-BI18 -> #REF!
A19: Daily Sales | C19: Week 3 | D19: 15 | E19: ='Hourly Customer'!$D$29 -> 0 | G19: =G18+E19-F19 -> #REF! | H19: Week 3 | I19: 15 | J19: ='Hourly Customer'!$D$29 -> 0 | L19: =L18+J19-K19 -> #REF! | M19: Week 3 | N19: 15 | O19: ='Hourly Customer'!$D$29 -> 0 | Q19: =Q18+O19-P19 -> #REF! | R19: Week 3 | S19: 15 | T19: ='Hourly Customer'!$D$29 -> 0 | V19: =V18+T19-U19 -> #REF! | W19: Week 3 | X19: 15 | Y19: ='Hourly Customer'!$D$29 -> 0 | AA19: =AA18+Y19-Z19 -> #REF! | AB19: Week 3 | AC19: 15 | AD19: ='Hourly Customer'!$D$29 -> 0 | AF19: =AF18+AD19-AE19 -> #REF! | AG19: Week 3 | AH19: 15 | AI19: ='Hourly Customer'!$D$29 -> 0 | AK19: =AK18+AI19-AJ19 -> #REF! | AL19: Week 3 | AM19: 15 | AN19: ='Hourly Customer'!$D$29 -> 0 | AP19: =AP18+AN19-AO19 -> #REF! | AQ19: Week 3 | AR19: 15 | AS19: ='Hourly Customer'!$D$29 -> 0 | AU19: =AU18+AS19-AT19 -> #REF! | AV19: Week 3 | AW19: 15 | AX19: ='Hourly Customer'!$D$29 -> 0 | AZ19: =AZ18+AX19-AY19 -> #REF! | BA19: Week 3 | BB19: 15 | BC19: ='Hourly Customer'!$D$29 -> 0 | BE19: =BE18+BC19-BD19 -> #REF! | BF19: Week 3 | BG19: 15 | BH19: ='Hourly Customer'!$D$29 -> 0 | BJ19: =BJ18+BH19-BI19 -> #REF!
A20: Daily Sales | D20: 16 | E20: ='Hourly Customer'!$D$29 -> 0 | G20: =G19+E20-F20 -> #REF! | I20: 16 | J20: ='Hourly Customer'!$D$29 -> 0 | L20: =L19+J20-K20 -> #REF! | N20: 16 | O20: ='Hourly Customer'!$D$29 -> 0 | Q20: =Q19+O20-P20 -> #REF! | S20: 16 | T20: ='Hourly Customer'!$D$29 -> 0 | V20: =V19+T20-U20 -> #REF! | X20: 16 | Y20: ='Hourly Customer'!$D$29 -> 0 | AA20: =AA19+Y20-Z20 -> #REF! | AC20: 16 | AD20: ='Hourly Customer'!$D$29 -> 0 | AF20: =AF19+AD20-AE20 -> #REF! | AH20: 16 | AI20: ='Hourly Customer'!$D$29 -> 0 | AK20: =AK19+AI20-AJ20 -> #REF! | AM20: 16 | AN20: ='Hourly Customer'!$D$29 -> 0 | AP20: =AP19+AN20-AO20 -> #REF! | AR20: 16 | AS20: ='Hourly Customer'!$D$29 -> 0 | AU20: =AU19+AS20-AT20 -> #REF! | AW20: 16 | AX20: ='Hourly Customer'!$D$29 -> 0 | AZ20: =AZ19+AX20-AY20 -> #REF! | BB20: 16 | BC20: ='Hourly Customer'!$D$29 -> 0 | BE20: =BE19+BC20-BD20 -> #REF! | BG20: 16 | BH20: ='Hourly Customer'!$D$29 -> 0 | BJ20: =BJ19+BH20-BI20 -> #REF!
A21: Daily Sales | B21: Administrative | D21: 17 | E21: ='Hourly Customer'!$D$29 -> 0 | F21: ='Monthly IS'!#REF! -> #REF! | G21: =G20+E21-F21 -> #REF! | I21: 17 | J21: ='Hourly Customer'!$D$29 -> 0 | K21: ='Monthly IS'!#REF! -> #REF! | L21: =L20+J21-K21 -> #REF! | N21: 17 | O21: ='Hourly Customer'!$D$29 -> 0 | P21: ='Monthly IS'!#REF! -> #REF! | Q21: =Q20+O21-P21 -> #REF! | S21: 17 | T21: ='Hourly Customer'!$D$29 -> 0 | U21: ='Monthly IS'!#REF! -> #REF! | V21: =V20+T21-U21 -> #REF! | X21: 17 | Y21: ='Hourly Customer'!$D$29 -> 0 | Z21: ='Monthly IS'!#REF! -> #REF! | AA21: =AA20+Y21-Z21 -> #REF! | AC21: 17 | AD21: ='Hourly Customer'!$D$29 -> 0 | AE21: ='Monthly IS'!#REF! -> #REF! | AF21: =AF20+AD21-AE21 -> #REF! | AH21: 17 | AI21: ='Hourly Customer'!$D$29 -> 0 | AJ21: ='Monthly IS'!#REF! -> #REF! | AK21: =AK20+AI21-AJ21 -> #REF! | AM21: 17 | AN21: ='Hourly Customer'!$D$29 -> 0 | AO21: ='Monthly IS'!#REF! -> #REF! | AP21: =AP20+AN21-AO21 -> #REF! | AR21: 17 | AS21: ='Hourly Customer'!$D$29 -> 0 | AT21: ='Monthly IS'!#REF! -> #REF! | AU21: =AU20+AS21-AT21 -> #REF! | AW21: 17 | AX21: ='Hourly Customer'!$D$29 -> 0 | AY21: ='Monthly IS'!#REF! -> #REF! | AZ21: =AZ20+AX21-AY21 -> #REF! | BB21: 17 | BC21: ='Hourly Customer'!$D$29 -> 0 | BD21: ='Monthly IS'!#REF! -> #REF! | BE21: =BE20+BC21-BD21 -> #REF! | BG21: 17 | BH21: ='Hourly Customer'!$D$29 -> 0 | BI21: ='Monthly IS'!#REF! -> #REF! | BJ21: =BJ20+BH21-BI21 -> #REF!
A22: Daily Sales | D22: 18 | E22: ='Hourly Customer'!$D$29 -> 0 | G22: =G21+E22-F22 -> #REF! | I22: 18 | J22: ='Hourly Customer'!$D$29 -> 0 | L22: =L21+J22-K22 -> #REF! | N22: 18 | O22: ='Hourly Customer'!$D$29 -> 0 | Q22: =Q21+O22-P22 -> #REF! | S22: 18 | T22: ='Hourly Customer'!$D$29 -> 0 | V22: =V21+T22-U22 -> #REF! | X22: 18 | Y22: ='Hourly Customer'!$D$29 -> 0 | AA22: =AA21+Y22-Z22 -> #REF! | AC22: 18 | AD22: ='Hourly Customer'!$D$29 -> 0 | AF22: =AF21+AD22-AE22 -> #REF! | AH22: 18 | AI22: ='Hourly Customer'!$D$29 -> 0 | AK22: =AK21+AI22-AJ22 -> #REF! | AM22: 18 | AN22: ='Hourly Customer'!$D$29 -> 0 | AP22: =AP21+AN22-AO22 -> #REF! | AR22: 18 | AS22: ='Hourly Customer'!$D$29 -> 0 | AU22: =AU21+AS22-AT22 -> #REF! | AW22: 18 | AX22: ='Hourly Customer'!$D$29 -> 0 | AZ22: =AZ21+AX22-AY22 -> #REF! | BB22: 18 | BC22: ='Hourly Customer'!$D$29 -> 0 | BE22: =BE21+BC22-BD22 -> #REF! | BG22: 18 | BH22: ='Hourly Customer'!$D$29 -> 0 | BJ22: =BJ21+BH22-BI22 -> #REF!
A23: Daily Sales | D23: 19 | E23: ='Hourly Customer'!$D$29 -> 0 | G23: =G22+E23-F23 -> #REF! | I23: 19 | J23: ='Hourly Customer'!$D$29 -> 0 | L23: =L22+J23-K23 -> #REF! | N23: 19 | O23: ='Hourly Customer'!$D$29 -> 0 | Q23: =Q22+O23-P23 -> #REF! | S23: 19 | T23: ='Hourly Customer'!$D$29 -> 0 | V23: =V22+T23-U23 -> #REF! | X23: 19 | Y23: ='Hourly Customer'!$D$29 -> 0 | AA23: =AA22+Y23-Z23 -> #REF! | AC23: 19 | AD23: ='Hourly Customer'!$D$29 -> 0 | AF23: =AF22+AD23-AE23 -> #REF! | AH23: 19 | AI23: ='Hourly Customer'!$D$29 -> 0 | AK23: =AK22+AI23-AJ23 -> #REF! | AM23: 19 | AN23: ='Hourly Customer'!$D$29 -> 0 | AP23: =AP22+AN23-AO23 -> #REF! | AR23: 19 | AS23: ='Hourly Customer'!$D$29 -> 0 | AU23: =AU22+AS23-AT23 -> #REF! | AW23: 19 | AX23: ='Hourly Customer'!$D$29 -> 0 | AZ23: =AZ22+AX23-AY23 -> #REF! | BB23: 19 | BC23: ='Hourly Customer'!$D$29 -> 0 | BE23: =BE22+BC23-BD23 -> #REF! | BG23: 19 | BH23: ='Hourly Customer'!$D$29 -> 0 | BJ23: =BJ22+BH23-BI23 -> #REF!
